Workbook

Sheet 교체현황_DB
A1: 교체ID | B1: 교체일자 | C1: 편성 | D1: 차호 | E1: 위치 | F1: 취거TM_시리얼 | G1: 취거TM_제작년도 | H1: 취거TM_제조사 | I1: 부착TM_시리얼 | J1: 부착TM_제작년도 | K1: 부착TM_제조사 | L1: 고장유형(선택) | M1: 고장코드(자동) | N1: 심각도(자동) | O1: 위험점수(자동) | P1: 고장성교체여부(자동) | Q1: 세부 고장내용 | R1: 취거품 상태(선택) | S1: 취거품 상태/조치비고 | T1: 데이터검토(자동)
A2: RP-0001 | B2: 44231 | C2: 111 | D2: 1711 | E2: 2 | F2: 88TWDH073 | G2: 1988 | H2: 현대중공업 | I2: 88091-48 | J2: 1989 | K2: 대우중공업 | L2: 절연파괴·소손·F/O | M2: =IFERROR(INDEX(고장심각도분류!$A$2:$A$8,MATCH(L2,고장심각도분류!$B$2:$B$8,0)),"") -> FC05 | N2: =IFERROR(INDEX(고장심각도분류!$C$2:$C$8,MATCH(L2,고장심각도분류!$B$2:$B$8,0)),"") -> 7 | O2: =IFERROR(INDEX(고장심각도분류!$D$2:$D$8,MATCH(L2,고장심각도분류!$B$2:$B$8,0)),"") -> 100 | P2: =IF(O2>0,"Y","N") -> Y | Q2: 눈유입, 정류자 그을림, 접지 소손 | T2: =IF(OR(B2="",C2="",E2="",F2="",I2="",L2="",R2=""),"확인필요","OK") -> 확인필요
A3: RP-0002 | B3: 44236 | C3: 111 | D3: 1711 | E3: 3 | F3: 296638-17 | G3: 1974 | H3: 히타치 | I3: 296638-19 | J3: 1974 | K3: 히타치 | L3: 절연파괴·소손·F/O | M3: =IFERROR(INDEX(고장심각도분류!$A$2:$A$8,MATCH(L3,고장심각도분류!$B$2:$B$8,0)),"") -> FC05 | N3: =IFERROR(INDEX(고장심각도분류!$C$2:$C$8,MATCH(L3,고장심각도분류!$B$2:$B$8,0)),"") -> 7 | O3: =IFERROR(INDEX(고장심각도분류!$D$2:$D$8,MATCH(L3,고장심각도분류!$B$2:$B$8,0)),"") -> 100 | P3: =IF(O3>0,"Y","N") -> Y | Q3: 눈유입(절연파괴) | R3: 정비불가 | S3: 정비불가(절연파괴, 폐기) | T3: =IF(OR(B3="",C3="",E3="",F3="",I3="",L3="",R3=""),"확인필요","OK") -> OK
A4: RP-0003 | B4: 44281 | C4: 112 | D4: 1712 | E4: 1 | F4: 88091-57 | G4: 1989 | H4: 대우중공업 | I4: 296633-10 | J4: 1973 | K4: 히타치 | L4: 절연파괴·소손·F/O | M4: =IFERROR(INDEX(고장심각도분류!$A$2:$A$8,MATCH(L4,고장심각도분류!$B$2:$B$8,0)),"") -> FC05 | N4: =IFERROR(INDEX(고장심각도분류!$C$2:$C$8,MATCH(L4,고장심각도분류!$B$2:$B$8,0)),"") -> 7 | O4: =IFERROR(INDEX(고장심각도분류!$D$2:$D$8,MATCH(L4,고장심각도분류!$B$2:$B$8,0)),"") -> 100 | P4: =IF(O4>0,"Y","N") -> Y | Q4: 접지 소손 | T4: =IF(OR(B4="",C4="",E4="",F4="",I4="",L4="",R4=""),"확인필요","OK") -> 확인필요
A5: RP-0004 | B5: 44281 | C5: 112 | D5: 1712 | E5: 2 | F5: 88091-59 | G5: 1989 | H5: 대우중공업 | I5: 7733026 | J5: 1977 | K5: 도시바 | L5: 브러쉬홀더 열화·계자코일 단락 | M5: =IFERROR(INDEX(고장심각도분류!$A$2:$A$8,MATCH(L5,고장심각도분류!$B$2:$B$8,0)),"") -> FC03 | N5: =IFERROR(INDEX(고장심각도분류!$C$2:$C$8,MATCH(L5,고장심각도분류!$B$2:$B$8,0)),"") -> 5 | O5: =IFERROR(INDEX(고장심각도분류!$D$2:$D$8,MATCH(L5,고장심각도분류!$B$2:$B$8,0)),"") -> 45 | P5: =IF(O5>0,"Y","N") -> Y | Q5: 홀더 열화 | T5: =IF(OR(B5="",C5="",E5="",F5="",I5="",L5="",R5=""),"확인필요","OK") -> 확인필요
A6: RP-0005 | B6: 44281 | C6: 112 | D6: 1712 | E6: 3 | F6: 296634-9 | G6: 1974 | H6: 히타치 | I6: 92TWDH050 | J6: 1992 | K6: 현대중공업 | L6: 브러쉬홀더 열화·계자코일 단락 | M6: =IFERROR(INDEX(고장심각도분류!$A$2:$A$8,MATCH(L6,고장심각도분류!$B$2:$B$8,0)),"") -> FC03 | N6: =IFERROR(INDEX(고장심각도분류!$C$2:$C$8,MATCH(L6,고장심각도분류!$B$2:$B$8,0)),"") -> 5 | O6: =IFERROR(INDEX(고장심각도분류!$D$2:$D$8,MATCH(L6,고장심각도분류!$B$2:$B$8,0)),"") -> 45 | P6: =IF(O6>0,"Y","N") -> Y | Q6: 홀더 열화 | T6: =IF(OR(B6="",C6="",E6="",F6="",I6="",L6="",R6=""),"확인필요","OK") -> 확인필요
A7: RP-0006 | B7: 44281 | C7: 112 | D7: 1712 | E7: 4 | F7: 92TWDH048 | G7: 1992 | H7: 현대중공업 | I7: 92TWDH063 | J7: 1992 | K7: 현대중공업 | L7: 절연파괴·소손·F/O | M7: =IFERROR(INDEX(고장심각도분류!$A$2:$A$8,MATCH(L7,고장심각도분류!$B$2:$B$8,0)),"") -> FC05 | N7: =IFERROR(INDEX(고장심각도분류!$C$2:$C$8,MATCH(L7,고장심각도분류!$B$2:$B$8,0)),"") -> 7 | O7: =IFERROR(INDEX(고장심각도분류!$D$2:$D$8,MATCH(L7,고장심각도분류!$B$2:$B$8,0)),"") -> 100 | P7: =IF(O7>0,"Y","N") -> Y | Q7: 접지 소손 | T7: =IF(OR(B7="",C7="",E7="",F7="",I7="",L7="",R7=""),"확인필요","OK") -> 확인필요
A8: RP-0007 | B8: 44286 | C8: 112 | D8: 1712 | E8: 1 | F8: 296633-10 | G8: 1973 | H8: 히타치 | I8: 296634-9 | J8: 1974 | K8: 히타치 | L8: 절연파괴·소손·F/O | M8: =IFERROR(INDEX(고장심각도분류!$A$2:$A$8,MATCH(L8,고장심각도분류!$B$2:$B$8,0)),"") -> FC05 | N8: =IFERROR(INDEX(고장심각도분류!$C$2:$C$8,MATCH(L8,고장심각도분류!$B$2:$B$8,0)),"") -> 7 | O8: =IFERROR(INDEX(고장심각도분류!$D$2:$D$8,MATCH(L8,고장심각도분류!$B$2:$B$8,0)),"") -> 100 | P8: =IF(O8>0,"Y","N") -> Y | Q8: 접지 소손 | T8: =IF(OR(B8="",C8="",E8="",F8="",I8="",L8="",R8=""),"확인필요","OK") -> 확인필요
A9: RP-0008 | B9: 44286 | C9: 112 | D9: 1712 | E9: 2 | F9: 7733026 | G9: 1977 | H9: 도시바 | I9: 88091-59 | J9: 1989 | K9: 대우중공업 | L9: 절연파괴·소손·F/O | M9: =IFERROR(INDEX(고장심각도분류!$A$2:$A$8,MATCH(L9,고장심각도분류!$B$2:$B$8,0)),"") -> FC05 | N9: =IFERROR(INDEX(고장심각도분류!$C$2:$C$8,MATCH(L9,고장심각도분류!$B$2:$B$8,0)),"") -> 7 | O9: =IFERROR(INDEX(고장심각도분류!$D$2:$D$8,MATCH(L9,고장심각도분류!$B$2:$B$8,0)),"") -> 100 | P9: =IF(O9>0,"Y","N") -> Y | Q9: 접지 소손 | T9: =IF(OR(B9="",C9="",E9="",F9="",I9="",L9="",R9=""),"확인필요","OK") -> 확인필요
A10: RP-0009 | B10: 44286 | C10: 112 | D10: 1712 | E10: 3 | F10: 92TWDH050 | G10: 1992 | H10: 현대중공업 | I10: 88091-57 | J10: 1989 | K10: 대우중공업 | L10: 절연파괴·소손·F/O | M10: =IFERROR(INDEX(고장심각도분류!$A$2:$A$8,MATCH(L10,고장심각도분류!$B$2:$B$8,0)),"") -> FC05 | N10: =IFERROR(INDEX(고장심각도분류!$C$2:$C$8,MATCH(L10,고장심각도분류!$B$2:$B$8,0)),"") -> 7 | O10: =IFERROR(INDEX(고장심각도분류!$D$2:$D$8,MATCH(L10,고장심각도분류!$B$2:$B$8,0)),"") -> 100 | P10: =IF(O10>0,"Y","N") -> Y | Q10: 절연파괴 | R10: 정비불가 | S10: 정비불가(절연파괴, 폐기) | T10: =IF(OR(B10="",C10="",E10="",F10="",I10="",L10="",R10=""),"확인필요","OK") -> OK
A11: RP-0010 | B11: 44351 | C11: 116 | D11: 1216 | E11: 1 | F11: 88TWDH116 | G11: 1988 | H11: 현대중공업 | I11: 7733026 | J11: 1977 | K11: 도시바 | L11: 정기·순환교체 | M11: =IFERROR(INDEX(고장심각도분류!$A$2:$A$8,MATCH(L11,고장심각도분류!$B$2:$B$8,0)),"") -> FC00 | N11: =IFERROR(INDEX(고장심각도분류!$C$2:$C$8,MATCH(L11,고장심각도분류!$B$2:$B$8,0)),"") -> 1 | O11: =IFERROR(INDEX(고장심각도분류!$D$2:$D$8,MATCH(L11,고장심각도분류!$B$2:$B$8,0)),"") -> 0 | P11: =IF(O11>0,"Y","N") -> N | Q11: 정기 | T11: =IF(OR(B11="",C11="",E11="",F11="",I11="",L11="",R11=""),"확인필요","OK") -> 확인필요
A12: RP-0011 | B12: 44351 | C12: 116 | D12: 1216 | E12: 2 | F12: 296640-11 | G12: 1974 | H12: 히타치 | I12: 296633-10 | J12: 1973 | K12: 히타치 | L12: 정기·순환교체 | M12: =IFERROR(INDEX(고장심각도분류!$A$2:$A$8,MATCH(L12,고장심각도분류!$B$2:$B$8,0)),"") -> FC00 | N12: =IFERROR(INDEX(고장심각도분류!$C$2:$C$8,MATCH(L12,고장심각도분류!$B$2:$B$8,0)),"") -> 1 | O12: =IFERROR(INDEX(고장심각도분류!$D$2:$D$8,MATCH(L12,고장심각도분류!$B$2:$B$8,0)),"") -> 0 | P12: =IF(O12>0,"Y","N") -> N | Q12: 정기 | T12: =IF(OR(B12="",C12="",E12="",F12="",I12="",L12="",R12=""),"확인필요","OK") -> 확인필요
A13: RP-0012 | B13: 44372 | C13: 114 | D13: 1114 | E13: 1 | F13: 98TWDH398 | G13: 1998 | H13: 현대중공업 | I13: 95TWDH297 | J13: 1995 | K13: 현대중공업 | L13: 절연파괴·소손·F/O | M13: =IFERROR(INDEX(고장심각도분류!$A$2:$A$8,MATCH(L13,고장심각도분류!$B$2:$B$8,0)),"") -> FC05 | N13: =IFERROR(INDEX(고장심각도분류!$C$2:$C$8,MATCH(L13,고장심각도분류!$B$2:$B$8,0)),"") -> 7 | O13: =IFERROR(INDEX(고장심각도분류!$D$2:$D$8,MATCH(L13,고장심각도분류!$B$2:$B$8,0)),"") -> 100 | P13: =IF(O13>0,"Y","N") -> Y | Q13: 접지 소손 | T13: =IF(OR(B13="",C13="",E13="",F13="",I13="",L13="",R13=""),"확인필요","OK") -> 확인필요
A14: RP-0013 | B14: 44377 | C14: 112 | D14: 1712 | E14: 1 | F14: 296634-9 | G14: 1974 | H14: 히타치 | I14: 92TWDH048 | J14: 1992 | K14: 현대중공업 | L14: 절연파괴·소손·F/O | M14: =IFERROR(INDEX(고장심각도분류!$A$2:$A$8,MATCH(L14,고장심각도분류!$B$2:$B$8,0)),"") -> FC05 | N14: =IFERROR(INDEX(고장심각도분류!$C$2:$C$8,MATCH(L14,고장심각도분류!$B$2:$B$8,0)),"") -> 7 | O14: =IFERROR(INDEX(고장심각도분류!$D$2:$D$8,MATCH(L14,고장심각도분류!$B$2:$B$8,0)),"") -> 100 | P14: =IF(O14>0,"Y","N") -> Y | Q14: 접지 소손 | T14: =IF(OR(B14="",C14="",E14="",F14="",I14="",L14="",R14=""),"확인필요","OK") -> 확인필요
A15: RP-0014 | B15: 44382 | C15: 116 | D15: 1716 | E15: 1 | F15: 89TWDH037 | G15: 1989 | H15: 현대중공업 | I15: 296640-11 | J15: 1974 | K15: 히타치 | L15: 절연파괴·소손·F/O | M15: =IFERROR(INDEX(고장심각도분류!$A$2:$A$8,MATCH(L15,고장심각도분류!$B$2:$B$8,0)),"") -> FC05 | N15: =IFERROR(INDEX(고장심각도분류!$C$2:$C$8,MATCH(L15,고장심각도분류!$B$2:$B$8,0)),"") -> 7 | O15: =IFERROR(INDEX(고장심각도분류!$D$2:$D$8,MATCH(L15,고장심각도분류!$B$2:$B$8,0)),"") -> 100 | P15: =IF(O15>0,"Y","N") -> Y | Q15: 고압배선 소손(절연파괴로 폐기) | R15: 정비불가 | S15: 정비불가(절연파괴, 폐기) | T15: =IF(OR(B15="",C15="",E15="",F15="",I15="",L15="",R15=""),"확인필요","OK") -> OK
A16: RP-0015 | B16: 44382 | C16: 116 | D16: 1716 | E16: 2 | F16: 7432512 | G16: 1974 | H16: 도시바 | I16: 88TWDH116 | J16: 1988 | K16: 현대중공업 | L16: 절연파괴·소손·F/O | M16: =IFERROR(INDEX(고장심각도분류!$A$2:$A$8,MATCH(L16,고장심각도분류!$B$2:$B$8,0)),"") -> FC05 | N16: =IFERROR(INDEX(고장심각도분류!$C$2:$C$8,MATCH(L16,고장심각도분류!$B$2:$B$8,0)),"") -> 7 | O16: =IFERROR(INDEX(고장심각도분류!$D$2:$D$8,MATCH(L16,고장심각도분류!$B$2:$B$8,0)),"") -> 100 | P16: =IF(O16>0,"Y","N") -> Y | Q16: 접지 소손 | T16: =IF(OR(B16="",C16="",E16="",F16="",I16="",L16="",R16=""),"확인필요","OK") -> 확인필요
A17: RP-0016 | B17: 44382 | C17: 116 | D17: 1716 | E17: 3 | F17: 88091-67 | G17: 1989 | H17: 대우중공업 | I17: 88TWDH073 | J17: 1988 | K17: 현대중공업 | L17: 절연파괴·소손·F/O | M17: =IFERROR(INDEX(고장심각도분류!$A$2:$A$8,MATCH(L17,고장심각도분류!$B$2:$B$8,0)),"") -> FC05 | N17: =IFERROR(INDEX(고장심각도분류!$C$2:$C$8,MATCH(L17,고장심각도분류!$B$2:$B$8,0)),"") -> 7 | O17: =IFERROR(INDEX(고장심각도분류!$D$2:$D$8,MATCH(L17,고장심각도분류!$B$2:$B$8,0)),"") -> 100 | P17: =IF(O17>0,"Y","N") -> Y | Q17: 접지 소손 | T17: =IF(OR(B17="",C17="",E17="",F17="",I17="",L17="",R17=""),"확인필요","OK") -> 확인필요
A18: RP-0017 | B18: 44382 | C18: 116 | D18: 1716 | E18: 4 | F18: 88TWDH113 | G18: 1988 | H18: 현대중공업 | I18: 297207-11 | J18: 1998 | K18: 현대중공업 | L18: 기타 | M18: =IFERROR(INDEX(고장심각도분류!$A$2:$A$8,MATCH(L18,고장심각도분류!$B$2:$B$8,0)),"") -> FC99 | N18: =IFERROR(INDEX(고장심각도분류!$C$2:$C$8,MATCH(L18,고장심각도분류!$B$2:$B$8,0)),"") -> 2 | O18: =IFERROR(INDEX(고장심각도분류!$D$2:$D$8,MATCH(L18,고장심각도분류!$B$2:$B$8,0)),"") -> 5 | P18: =IF(O18>0,"Y","N") -> Y | T18: =IF(OR(B18="",C18="",E18="",F18="",I18="",L18="",R18=""),"확인필요","OK") -> 확인필요
A19: RP-0018 | B19: 44392 | C19: 113 | D19: 1813 | E19: 3 | F19: 88091-55 | G19: 1989 | H19: 대우중공업 | I19: 297207-11 | J19: 1974 | K19: 히타치 | L19: 절연파괴·소손·F/O | M19: =IFERROR(INDEX(고장심각도분류!$A$2:$A$8,MATCH(L19,고장심각도분류!$B$2:$B$8,0)),"") -> FC05 | N19: =IFERROR(INDEX(고장심각도분류!$C$2:$C$8,MATCH(L19,고장심각도분류!$B$2:$B$8,0)),"") -> 7 | O19: =IFERROR(INDEX(고장심각도분류!$D$2:$D$8,MATCH(L19,고장심각도분류!$B$2:$B$8,0)),"") -> 100 | P19: =IF(O19>0,"Y","N") -> Y | Q19: 접지 소손 | R19: 현차취부 | S19: 116편성 7호차 TM 취거하여 취부 | T19: =IF(OR(B19="",C19="",E19="",F19="",I19="",L19="",R19=""),"확인필요","OK") -> OK
A20: RP-0019 | B20: 44392 | C20: 113 | D20: 1813 | E20: 4 | F20: 94101-88 | G20: 1994 | H20: 대우중공업 | I20: 88TWDH073 | J20: 1988 | K20: 현대중공업 | L20: 절연파괴·소손·F/O | M20: =IFERROR(INDEX(고장심각도분류!$A$2:$A$8,MATCH(L20,고장심각도분류!$B$2:$B$8,0)),"") -> FC05 | N20: =IFERROR(INDEX(고장심각도분류!$C$2:$C$8,MATCH(L20,고장심각도분류!$B$2:$B$8,0)),"") -> 7 | O20: =IFERROR(INDEX(고장심각도분류!$D$2:$D$8,MATCH(L20,고장심각도분류!$B$2:$B$8,0)),"") -> 100 | P20: =IF(O20>0,"Y","N") -> Y | Q20: 접지 소손 | T20: =IF(OR(B20="",C20="",E20="",F20="",I20="",L20="",R20=""),"확인필요","OK") -> 확인필요
A21: RP-0020 | B21: 44392 | C21: 113 | D21: 1713 | E21: 3 | F21: 64057 | G21: 1977 | H21: 미쓰비시 | I21: 88TWDH116 | J21: 1988 | K21: 현대중공업 | L21: 절연파괴·소손·F/O | M21: =IFERROR(INDEX(고장심각도분류!$A$2:$A$8,MATCH(L21,고장심각도분류!$B$2:$B$8,0)),"") -> FC05 | N21: =IFERROR(INDEX(고장심각도분류!$C$2:$C$8,MATCH(L21,고장심각도분류!$B$2:$B$8,0)),"") -> 7 | O21: =IFERROR(INDEX(고장심각도분류!$D$2:$D$8,MATCH(L21,고장심각도분류!$B$2:$B$8,0)),"") -> 100 | P21: =IF(O21>0,"Y","N") -> Y | Q21: 접지 소손 | T21: =IF(OR(B21="",C21="",E21="",F21="",I21="",L21="",R21=""),"확인필요","OK") -> 확인필요
A22: RP-0021 | B22: 44392 | C22: 113 | D22: 1713 | E22: 4 | F22: 297207-4 | G22: 1974 | H22: 히타치 | I22: 296640-11 | J22: 1974 | K22: 히타치 | L22: 절연파괴·소손·F/O | M22: =IFERROR(INDEX(고장심각도분류!$A$2:$A$8,MATCH(L22,고장심각도분류!$B$2:$B$8,0)),"") -> FC05 | N22: =IFERROR(INDEX(고장심각도분류!$C$2:$C$8,MATCH(L22,고장심각도분류!$B$2:$B$8,0)),"") -> 7 | O22: =IFERROR(INDEX(고장심각도분류!$D$2:$D$8,MATCH(L22,고장심각도분류!$B$2:$B$8,0)),"") -> 100 | P22: =IF(O22>0,"Y","N") -> Y | Q22: 접지소손 | T22: =IF(OR(B22="",C22="",E22="",F22="",I22="",L22="",R22=""),"확인필요","OK") -> 확인필요
A23: RP-0022 | B23: 44400 | C23: 116 | D23: 1716 | E23: 1 | F23: - | G23: - | H23: - | I23: 7432512 | J23: 1974 | K23: 도시바 | L23: 기타 | M23: =IFERROR(INDEX(고장심각도분류!$A$2:$A$8,MATCH(L23,고장심각도분류!$B$2:$B$8,0)),"") -> FC99 | N23: =IFERROR(INDEX(고장심각도분류!$C$2:$C$8,MATCH(L23,고장심각도분류!$B$2:$B$8,0)),"") -> 2 | O23: =IFERROR(INDEX(고장심각도분류!$D$2:$D$8,MATCH(L23,고장심각도분류!$B$2:$B$8,0)),"") -> 5 | P23: =IF(O23>0,"Y","N") -> Y | T23: =IF(OR(B23="",C23="",E23="",F23="",I23="",L23="",R23=""),"확인필요","OK") -> 확인필요
A24: RP-0023 | B24: 44400 | C24: 116 | D24: 1716 | E24: 2 | F24: - | G24: - | H24: - | I24: 88091-67 | J24: 1989 | K24: 대우중공업 | L24: 기타 | M24: =IFERROR(INDEX(고장심각도분류!$A$2:$A$8,MATCH(L24,고장심각도분류!$B$2:$B$8,0)),"") -> FC99 | N24: =IFERROR(INDEX(고장심각도분류!$C$2:$C$8,MATCH(L24,고장심각도분류!$B$2:$B$8,0)),"") -> 2 | O24: =IFERROR(INDEX(고장심각도분류!$D$2:$D$8,MATCH(L24,고장심각도분류!$B$2:$B$8,0)),"") -> 5 | P24: =IF(O24>0,"Y","N") -> Y | T24: =IF(OR(B24="",C24="",E24="",F24="",I24="",L24="",R24=""),"확인필요","OK") -> 확인필요
A25: RP-0024 | B25: 44400 | C25: 116 | D25: 1716 | E25: 3 | F25: - | G25: - | H25: - | I25: 88TWDH113 | J25: 1988 | K25: 현대중공업 | L25: 기타 | M25: =IFERROR(INDEX(고장심각도분류!$A$2:$A$8,MATCH(L25,고장심각도분류!$B$2:$B$8,0)),"") -> FC99 | N25: =IFERROR(INDEX(고장심각도분류!$C$2:$C$8,MATCH(L25,고장심각도분류!$B$2:$B$8,0)),"") -> 2 | O25: =IFERROR(INDEX(고장심각도분류!$D$2:$D$8,MATCH(L25,고장심각도분류!$B$2:$B$8,0)),"") -> 5 | P25: =IF(O25>0,"Y","N") -> Y | T25: =IF(OR(B25="",C25="",E25="",F25="",I25="",L25="",R25=""),"확인필요","OK") -> 확인필요
A26: RP-0025 | B26: 44400 | C26: 116 | D26: 1716 | E26: 4 | F26: - | G26: - | H26: - | I26: 98TWDH398 | J26: 1998 | K26: 현대중공업 | L26: 기타 | M26: =IFERROR(INDEX(고장심각도분류!$A$2:$A$8,MATCH(L26,고장심각도분류!$B$2:$B$8,0)),"") -> FC99 | N26: =IFERROR(INDEX(고장심각도분류!$C$2:$C$8,MATCH(L26,고장심각도분류!$B$2:$B$8,0)),"") -> 2 | O26: =IFERROR(INDEX(고장심각도분류!$D$2:$D$8,MATCH(L26,고장심각도분류!$B$2:$B$8,0)),"") -> 5 | P26: =IF(O26>0,"Y","N") -> Y | T26: =IF(OR(B26="",C26="",E26="",F26="",I26="",L26="",R26=""),"확인필요","OK") -> 확인필요
A27: RP-0026 | B27: 44412 | C27: 112 | D27: 1712 | E27: 1 | F27: 92TWDH048 | G27: 1992 | H27: 현대중공업 | I27: 296634-9 | J27: 1989 | K27: 대우중공업 | L27: 절연파괴·소손·F/O | M27: =IFERROR(INDEX(고장심각도분류!$A$2:$A$8,MATCH(L27,고장심각도분류!$B$2:$B$8,0)),"") -> FC05 | N27: =IFERROR(INDEX(고장심각도분류!$C$2:$C$8,MATCH(L27,고장심각도분류!$B$2:$B$8,0)),"") -> 7 | O27: =IFERROR(INDEX(고장심각도분류!$D$2:$D$8,MATCH(L27,고장심각도분류!$B$2:$B$8,0)),"") -> 100 | P27: =IF(O27>0,"Y","N") -> Y | Q27: 접지 소손 | R27: 현차취부 | S27: 88091-59(2위 -> 1위 이동) / 2위 296634-9 취부 | T27: =IF(OR(B27="",C27="",E27="",F27="",I27="",L27="",R27=""),"확인필요","OK") -> OK
A28: RP-0027 | B28: 44471 | C28: 116 | D28: 1716 | E28: 4 | F28: 98TWDH398 | G28: 1998 | H28: 현대중공업 | I28: 64057 | J28: 1977 | K28: 미쓰비시 | L28: 절연파괴·소손·F/O | M28: =IFERROR(INDEX(고장심각도분류!$A$2:$A$8,MATCH(L28,고장심각도분류!$B$2:$B$8,0)),"") -> FC05 | N28: =IFERROR(INDEX(고장심각도분류!$C$2:$C$8,MATCH(L28,고장심각도분류!$B$2:$B$8,0)),"") -> 7 | O28: =IFERROR(INDEX(고장심각도분류!$D$2:$D$8,MATCH(L28,고장심각도분류!$B$2:$B$8,0)),"") -> 100 | P28: =IF(O28>0,"Y","N") -> Y | Q28: 브러쉬홀더 리드선 절손 및 열화, 정류자 F/O | T28: =IF(OR(B28="",C28="",E28="",F28="",I28="",L28="",R28=""),"확인필요","OK") -> 확인필요
A29: RP-0028 | B29: 44497 | C29: 111 | D29: 1811 | E29: 1 | F29: 87TWDH047 | G29: 1987 | H29: 현대중공업 | I29: 94101-88 | J29: 1994 | K29: 대우중공업 | L29: 절연파괴·소손·F/O | M29: =IFERROR(INDEX(고장심각도분류!$A$2:$A$8,MATCH(L29,고장심각도분류!$B$2:$B$8,0)),"") -> FC05 | N29: =IFERROR(INDEX(고장심각도분류!$C$2:$C$8,MATCH(L29,고장심각도분류!$B$2:$B$8,0)),"") -> 7 | O29: =IFERROR(INDEX(고장심각도분류!$D$2:$D$8,MATCH(L29,고장심각도분류!$B$2:$B$8,0)),"") -> 100 | P29: =IF(O29>0,"Y","N") -> Y | Q29: 접지 소손, 정류자 F/O | R29: 정비불가 | S29: 정비불가(절연파괴, 폐기) | T29: =IF(OR(B29="",C29="",E29="",F29="",I29="",L29="",R29=""),"확인필요","OK") -> OK
A30: RP-0029 | B30: 44551 | C30: 111 | D30: 1711 | E30: 3 | F30: 296638-19 | G30: 1974 | H30: 히타치 | I30: 92TWDH048 | J30: 1992 | K30: 현대중공업 | L30: 절연파괴·소손·F/O | M30: =IFERROR(INDEX(고장심각도분류!$A$2:$A$8,MATCH(L30,고장심각도분류!$B$2:$B$8,0)),"") -> FC05 | N30: =IFERROR(INDEX(고장심각도분류!$C$2:$C$8,MATCH(L30,고장심각도분류!$B$2:$B$8,0)),"") -> 7 | O30: =IFERROR(INDEX(고장심각도분류!$D$2:$D$8,MATCH(L30,고장심각도분류!$B$2:$B$8,0)),"") -> 100 | P30: =IF(O30>0,"Y","N") -> Y | Q30: 절연파괴, 정류자 F/O | T30: =IF(OR(B30="",C30="",E30="",F30="",I30="",L30="",R30=""),"확인필요","OK") -> 확인필요
A31: RP-0030 | B31: 44613 | C31: 112 | D31: 1512 | E31: 2 | F31: 8833344 | G31: 1988 | H31: 도시바 | I31: 88091-55 | J31: 1989 | K31: 대우중공업 | L31: 절연파괴·소손·F/O | M31: =IFERROR(INDEX(고장심각도분류!$A$2:$A$8,MATCH(L31,고장심각도분류!$B$2:$B$8,0)),"") -> FC05 | N31: =IFERROR(INDEX(고장심각도분류!$C$2:$C$8,MATCH(L31,고장심각도분류!$B$2:$B$8,0)),"") -> 7 | O31: =IFERROR(INDEX(고장심각도분류!$D$2:$D$8,MATCH(L31,고장심각도분류!$B$2:$B$8,0)),"") -> 100 | P31: =IF(O31>0,"Y","N") -> Y | Q31: 절연불량 9M옴 | R31: 정비불가 | S31: 정비불가(절연파괴) | T31: =IF(OR(B31="",C31="",E31="",F31="",I31="",L31="",R31=""),"확인필요","OK") -> OK
A32: RP-0031 | B32: 44615 | C32: 111 | D32: 1711 | E32: 3 | F32: 92TWDH048 | G32: 1992 | H32: 현대중공업 | I32: 297207-4 | J32: 1974 | K32: 히타치 | L32: 절연파괴·소손·F/O | M32: =IFERROR(INDEX(고장심각도분류!$A$2:$A$8,MATCH(L32,고장심각도분류!$B$2:$B$8,0)),"") -> FC05 | N32: =IFERROR(INDEX(고장심각도분류!$C$2:$C$8,MATCH(L32,고장심각도분류!$B$2:$B$8,0)),"") -> 7 | O32: =IFERROR(INDEX(고장심각도분류!$D$2:$D$8,MATCH(L32,고장심각도분류!$B$2:$B$8,0)),"") -> 100 | P32: =IF(O32>0,"Y","N") -> Y | Q32: 절연파괴 | R32: 정비불가 | S32: 정비불가(절연파괴) | T32: =IF(OR(B32="",C32="",E32="",F32="",I32="",L32="",R32=""),"확인필요","OK") -> OK
A33: RP-0032 | B33: 44615 | C33: 111 | D33: 1711 | E33: 2 | F33: 88091-48 | G33: 1989 | H33: 대우중공업 | I33: 98TWDH398 | J33: 1998 | K33: 현대중공업 | L33: 절연파괴·소손·F/O | M33: =IFERROR(INDEX(고장심각도분류!$A$2:$A$8,MATCH(L33,고장심각도분류!$B$2:$B$8,0)),"") -> FC05 | N33: =IFERROR(INDEX(고장심각도분류!$C$2:$C$8,MATCH(L33,고장심각도분류!$B$2:$B$8,0)),"") -> 7 | O33: =IFERROR(INDEX(고장심각도분류!$D$2:$D$8,MATCH(L33,고장심각도분류!$B$2:$B$8,0)),"") -> 100 | P33: =IF(O33>0,"Y","N") -> Y | Q33: 정류자 F/O | T33: =IF(OR(B33="",C33="",E33="",F33="",I33="",L33="",R33=""),"확인필요","OK") -> 확인필요
A34: RP-0033 | B34: 44630 | C34: 116 | D34: 1116 | E34: 1 | F34: 88091-87 | G34: 1989 | H34: 대우중공업 | I34: 296638-19 | J34: 1974 | K34: 히타치 | L34: 브러쉬홀더 열화·계자코일 단락 | M34: =IFERROR(INDEX(고장심각도분류!$A$2:$A$8,MATCH(L34,고장심각도분류!$B$2:$B$8,0)),"") -> FC03 | N34: =IFERROR(INDEX(고장심각도분류!$C$2:$C$8,MATCH(L34,고장심각도분류!$B$2:$B$8,0)),"") -> 5 | O34: =IFERROR(INDEX(고장심각도분류!$D$2:$D$8,MATCH(L34,고장심각도분류!$B$2:$B$8,0)),"") -> 45 | P34: =IF(O34>0,"Y","N") -> Y | Q34: 홀더 열화, 절연저항 양호 | T34: =IF(OR(B34="",C34="",E34="",F34="",I34="",L34="",R34=""),"확인필요","OK") -> 확인필요
A35: RP-0034 | B35: 44630 | C35: 116 | D35: 1116 | E35: 2 | F35: 296637-8 | G35: 1974 | H35: 히타치 | I35: 88091-48 | J35: 1989 | K35: 대우중공업 | L35: 브러쉬홀더 열화·계자코일 단락 | M35: =IFERROR(INDEX(고장심각도분류!$A$2:$A$8,MATCH(L35,고장심각도분류!$B$2:$B$8,0)),"") -> FC03 | N35: =IFERROR(INDEX(고장심각도분류!$C$2:$C$8,MATCH(L35,고장심각도분류!$B$2:$B$8,0)),"") -> 5 | O35: =IFERROR(INDEX(고장심각도분류!$D$2:$D$8,MATCH(L35,고장심각도분류!$B$2:$B$8,0)),"") -> 45 | P35: =IF(O35>0,"Y","N") -> Y | Q35: 홀더 열화, 절연저항 양호 | T35: =IF(OR(B35="",C35="",E35="",F35="",I35="",L35="",R35=""),"확인필요","OK") -> 확인필요
A36: RP-0035 | B36: 44631 | C36: 116 | D36: 1116 | E36: 1 | F36: 296638-19 | G36: 1974 | H36: 히타치 | I36: 88TWDH103 | J36: 1988 | K36: 현대중공업 | L36: 절연파괴·소손·F/O | M36: =IFERROR(INDEX(고장심각도분류!$A$2:$A$8,MATCH(L36,고장심각도분류!$B$2:$B$8,0)),"") -> FC05 | N36: =IFERROR(INDEX(고장심각도분류!$C$2:$C$8,MATCH(L36,고장심각도분류!$B$2:$B$8,0)),"") -> 7 | O36: =IFERROR(INDEX(고장심각도분류!$D$2:$D$8,MATCH(L36,고장심각도분류!$B$2:$B$8,0)),"") -> 100 | P36: =IF(O36>0,"Y","N") -> Y | Q36: 절연저항 불량, 계자 F/O | R36: 정비불가 | S36: 정비불가(절연파괴), 111편성 TM사용 | T36: =IF(OR(B36="",C36="",E36="",F36="",I36="",L36="",R36=""),"확인필요","OK") -> OK
A37: RP-0036 | B37: 44631 | C37: 116 | D37: 1116 | E37: 2 | F37: 88091-48 | G37: 1989 | H37: 대우중공업 | I37: 96TWDH244 | J37: 1996 | K37: 현대중공업 | L37: 절연저항·물유입·세이프티 이상 | M37: =IFERROR(INDEX(고장심각도분류!$A$2:$A$8,MATCH(L37,고장심각도분류!$B$2:$B$8,0)),"") -> FC02 | N37: =IFERROR(INDEX(고장심각도분류!$C$2:$C$8,MATCH(L37,고장심각도분류!$B$2:$B$8,0)),"") -> 4 | O37: =IFERROR(INDEX(고장심각도분류!$D$2:$D$8,MATCH(L37,고장심각도분류!$B$2:$B$8,0)),"") -> 20 | P37: =IF(O37>0,"Y","N") -> Y | Q37: 절연저항 불량 | R37: 확인필요 | S37: 111편성 TM사용 | T37: =IF(OR(B37="",C37="",E37="",F37="",I37="",L37="",R37=""),"확인필요","OK") -> OK
A38: RP-0037 | B38: 44636 | C38: 111 | D38: 1211 | E38: 1 | F38: - | G38: - | H38: - | I38: 296637-8 | J38: 1974 | K38: 히타치 | L38: 기타 | M38: =IFERROR(INDEX(고장심각도분류!$A$2:$A$8,MATCH(L38,고장심각도분류!$B$2:$B$8,0)),"") -> FC99 | N38: =IFERROR(INDEX(고장심각도분류!$C$2:$C$8,MATCH(L38,고장심각도분류!$B$2:$B$8,0)),"") -> 2 | O38: =IFERROR(INDEX(고장심각도분류!$D$2:$D$8,MATCH(L38,고장심각도분류!$B$2:$B$8,0)),"") -> 5 | P38: =IF(O38>0,"Y","N") -> Y | R38: 예비품전환 | S38: 예비품 부족으로 111편성 TM사용 | T38: =IF(OR(B38="",C38="",E38="",F38="",I38="",L38="",R38=""),"확인필요","OK") -> OK
A39: RP-0038 | B39: 44636 | C39: 111 | D39: 1211 | E39: 2 | F39: - | G39: - | H39: - | I39: 88091-87 | J39: 1989 | K39: 대우중공업 | L39: 기타 | M39: =IFERROR(INDEX(고장심각도분류!$A$2:$A$8,MATCH(L39,고장심각도분류!$B$2:$B$8,0)),"") -> FC99 | N39: =IFERROR(INDEX(고장심각도분류!$C$2:$C$8,MATCH(L39,고장심각도분류!$B$2:$B$8,0)),"") -> 2 | O39: =IFERROR(INDEX(고장심각도분류!$D$2:$D$8,MATCH(L39,고장심각도분류!$B$2:$B$8,0)),"") -> 5 | P39: =IF(O39>0,"Y","N") -> Y | R39: 예비품전환 | S39: 예비품 부족으로 111편성 TM사용 | T39: =IF(OR(B39="",C39="",E39="",F39="",I39="",L39="",R39=""),"확인필요","OK") -> OK
A40: RP-0039 | B40: 44636 | C40: 111 | D40: 1211 | E40: 3 | F40: - | G40: - | H40: - | I40: 88TWDH099 | J40: 1988 | K40: 현대중공업 | L40: 기타 | M40: =IFERROR(INDEX(고장심각도분류!$A$2:$A$8,MATCH(L40,고장심각도분류!$B$2:$B$8,0)),"") -> FC99 | N40: =IFERROR(INDEX(고장심각도분류!$C$2:$C$8,MATCH(L40,고장심각도분류!$B$2:$B$8,0)),"") -> 2 | O40: =IFERROR(INDEX(고장심각도분류!$D$2:$D$8,MATCH(L40,고장심각도분류!$B$2:$B$8,0)),"") -> 5 | P40: =IF(O40>0,"Y","N") -> Y | R40: 예비품전환 | S40: 예비품 부족으로 111편성 TM사용 | T40: =IF(OR(B40="",C40="",E40="",F40="",I40="",L40="",R40=""),"확인필요","OK") -> OK
...

Sheet 고장심각도분류
A1: 고장코드 | B1: 표준고장유형 | C1: 심각도 | D1: 위험점수 | E1: 표시색 | F1: 체크박스/선택 기준 | G1: 대표 키워드 | H1: 비고 | J1: 취거품상태_선택목록 | K1: 설명
A2: FC00 | B2: 정기·순환교체 | C2: 1 | D2: 0 | E2: 회색 | F2: 고장성 낮음 | G2: 정기, 순환, 예방, 수선예비품 순환 | H2: 위험점수 0점 | J2: 정상/재사용가능 | K2: 육안 및 기본점검 결과 재사용 가능
A3: FC01 | B3: 정류자·브러쉬 경미 이상 | C3: 3 | D3: 10 | E3: 초록 | F3: 경미 이상 | G3: 정류자 그을림, MOCD, 브러쉬홀더 마모한도, 브러쉬 흠집, 흠집 | H3: 점검/추적 | J3: 정비필요 | K3: 정비 후 재사용 가능성 있음
A4: FC02 | B4: 절연저항·물유입·세이프티 이상 | C4: 4 | D4: 20 | E4: 연두 | F4: 주의 | G4: 절연저항 불량, 절연불량, 물유입, 세이프티 너트, GR | H4: 주의 관찰 | J4: 정비완료 | K4: 정비 완료 후 예비품 또는 재사용 가능
A5: FC03 | B5: 브러쉬홀더 열화·계자코일 단락 | C5: 5 | D5: 45 | E5: 노랑 | F5: 중간위험 | G5: 브러쉬홀더 열화, 홀더 열화, 계자 코일 단락, 계자코일 단락 | H5: 고장성 교체 | J5: 정비불가 | K5: 수리/정비 불가 판정
A6: FC04 | B6: 리드선 절손·열화 | C6: 6 | D6: 70 | E6: 주황 | F6: 고위험 | G6: 리드선 절손, 리드선 열화, 절손 및 열화 | H6: 우선 점검 | J6: 폐기/불용 | K6: 폐기 또는 불용 처리 대상
A7: FC05 | B7: 절연파괴·소손·F/O | C7: 7 | D7: 100 | E7: 빨강 | F7: 치명 | G7: 정류자 F/O, 계자 F/O, 절연파괴, 접지 소손, 접지소손, 고압배선 소손, 소손, 폐기, 브러쉬절손, 눈유입 | H7: 우선 교체/불용 검토 | J7: 예비품전환 | K7: 예비품으로 전환 또는 보관
A8: FC99 | B8: 기타 | C8: 2 | D8: 5 | E8: 회색 | F8: 표준 유형 외 | G8: 기타 | H8: 필요 시 표준유형으로 재분류 | J8: 현차취부 | K8: 타 편성 또는 동일 편성에 취부
J9: 확인필요 | K9: 자료상태 확인 필요
J10: 기타 | K10: 표준 상태 외 별도 기재 필요
